<?xml version="1.0"?>

<robot name="sphero"
       xmlns:sensor="http://playerstage.sourceforge.net/gazebo/xmlschema/#sensor"
       xmlns:controller="http://playerstage.sourceforge.net/gazebo/xmlschema/#controller"
       xmlns:interface="http://playerstage.sourceforge.net/gazebo/xmlschema/#interface"
       xmlns:xacro="http://ros.org/wiki/xacro">

  <property name="M_PI" value="3.14159"/>
  <property name="SCALE" value="0.0254"/>

  <material name="Green">
    <color rgba="0.0 0.8 0.0 1.0"/>
  </material>

  <link name="base_footprint">
    <visual>
      <origin xyz="0 0 0" rpy="0 0 0" />
      <geometry>
        <box size="0.001 0.001 0.001" />
      </geometry>
      <material name="Green" />
    </visual>
  
    <collision>
      <origin xyz="0.0 0.0 0.0" rpy="0 0 0" />
      <geometry>
	    <box size="0.001 0.001 0.001" />
      </geometry>
    </collision>
  </link>
   
  <link name="base_link">
    <visual>
      <origin xyz=" 0 0 0" rpy="0 0 0" />
      <geometry>
	    <mesh filename="package://sphero_description/meshes/Sphero_Textured.dae"/>
      </geometry>
    </visual>

    <collision>
      <origin xyz="0.0 0.0 0.0" rpy="0 0 0" />
      <geometry>
        <sphere radius="0.0381"/>
      </geometry>
    </collision>
  </link>
  
  <joint name="base_footprint_joint" type="continuous">
	<origin xyz="0 0 0.038" rpy="0 0 0" />        
	<parent link="base_footprint"/>
	<child link="base_link" />
  </joint>
  
</robot>
